Time slot   0
ld_routine
Time slot   1
	Loaded a process at input/proc/p0s, PID: 1 PRIO: 130
	CPU 1: Dispatched process  1
Time slot   2
	Loaded a process at input/proc/s3, PID: 2 PRIO: 39
Time slot   3
	CPU 2: Dispatched process  2
	CPU 1: Put process  1 to run queue
	CPU 1: Dispatched process  1
Time slot   4
	Loaded a process at input/proc/m1s, PID: 3 PRIO: 15
	CPU 0: Dispatched process  3
Time slot   5
	CPU 1: Put process  1 to run queue
	CPU 1: Dispatched process  1
	CPU 2: Put process  2 to run queue
	CPU 2: Dispatched process  2
Time slot   6
	CPU 0: Put process  3 to run queue
	Loaded a process at input/proc/s2, PID: 4 PRIO: 120
	CPU 0: Dispatched process  3
write region=1 offset=20 value=100
print_pgtbl: 0 - 1024
00000000: 80000001
00000004: 80000000
00000008: 80000003
00000012: 80000002
Time slot   7
	CPU 3: Dispatched process  4
	CPU 2: Put process  2 to run queue
	CPU 2: Dispatched process  2
	CPU 1: Put process  1 to run queue
	CPU 1: Dispatched process  1
read region=1 offset=20 value=100
print_pgtbl: 0 - 1024
00000000: 80000001
00000004: 80000000
00000008: 80000003
00000012: 80000002
MEMORY_dump.
	Loaded a process at input/proc/m0s, PID: 5 PRIO: 120
Time slot   8
write region=2 offset=20 value=102
print_pgtbl: 0 - 1024
00000000: 80000001
00000004: 80000000
00000008: 80000003
00000012: 80000002
WRITE operation failed.
	CPU 0: Put process  3 to run queue
	CPU 0: Dispatched process  3
	Loaded a process at input/proc/p1s, PID: 6 PRIO: 15
Time slot   9
	CPU 2: Put process  2 to run queue
	CPU 2: Dispatched process  6
	CPU 1: Put process  1 to run queue
	CPU 1: Dispatched process  2
	CPU 3: Put process  4 to run queue
	CPU 3: Dispatched process  5
Time slot  10
	CPU 0: Processed  3 has finished
	CPU 0: Dispatched process  4
	Loaded a process at input/proc/s0, PID: 7 PRIO: 38
	CPU 2: Put process  6 to run queue
	CPU 2: Dispatched process  6
	CPU 1: Put process  2 to run queue
	CPU 1: Dispatched process  7
	CPU 3: Put process  5 to run queue
	CPU 3: Dispatched process  2
Time slot  11
Time slot  12
	CPU 0: Put process  4 to run queue
	CPU 0: Dispatched process  5
	CPU 3: Put process  2 to run queue
Time slot  13
	CPU 3: Dispatched process  2
	CPU 2: Put process  6 to run queue
	CPU 2: Dispatched process  6
	CPU 1: Put process  7 to run queue
	CPU 1: Dispatched process  7
Time slot  14
	CPU 0: Put process  5 to run queue
	CPU 0: Dispatched process  4
	CPU 3: Put process  2 to run queue
Time slot  15
	CPU 2: Put process  6 to run queue
	CPU 2: Dispatched process  6
	CPU 1: Put process  7 to run queue
	CPU 3: Dispatched process  2
	CPU 1: Dispatched process  7
Time slot  16
	Loaded a process at input/proc/s1, PID: 8 PRIO: 0
	CPU 0: Put process  4 to run queue
	CPU 0: Dispatched process  8
	CPU 3: Put process  2 to run queue
Time slot  17
	CPU 3: Dispatched process  2
	CPU 2: Put process  6 to run queue
	CPU 2: Dispatched process  6
	CPU 1: Put process  7 to run queue
	CPU 1: Dispatched process  7
Time slot  18
	CPU 0: Put process  8 to run queue
	CPU 0: Dispatched process  8
	CPU 3: Put process  2 to run queue
Time slot  19
	CPU 3: Dispatched process  2
	CPU 2: Put process  6 to run queue
	CPU 2: Dispatched process  6
	CPU 1: Put process  7 to run queue
	CPU 1: Dispatched process  7
	CPU 3: Processed  2 has finished
Time slot  20
	CPU 3: Dispatched process  5
write region=1 offset=20 value=102
print_pgtbl: 0 - 768	CPU 2: Processed  6 has finished
	CPU 0: Put process  8 to run queue
	CPU 0: Dispatched process  8

00000000: 80000008
00000004: 80000007
00000008: 80000009
	CPU 2: Dispatched process  4
write region=2 offset=1000 value=1
Time slot  21
print_pgtbl: 0 - 768
00000000: 80000008
00000004: 80000007
00000008: 80000009
WRITE operation failed.
	CPU 1: Put process  7 to run queue
	CPU 1: Dispatched process  7
	CPU 3: Processed  5 has finished
Time slot  22
	CPU 3: Dispatched process  1
READ operation failed.
read region=2 offset=20 value=105
print_pgtbl: 0 - 1024
00000000: 80000001
	CPU 0: Put process  8 to run queue
	CPU 2: Put process  4 to run queue
	CPU 0: Dispatched process  8
00000004: 80000000
	CPU 2: Dispatched process  4
00000008: 80000003
00000012: 80000002
MEMORY_dump.
write region=3 offset=20 value=103
Time slot  23
print_pgtbl: 0 - 1024
00000000: 80000001
	CPU 1: Put process  7 to run queue
	CPU 0: Processed  8 has finished
00000004: 80000000
00000008: 80000003
00000012: 80000002
WRITE operation failed.
	CPU 1: Dispatched process  7
	CPU 0 stopped
	CPU 3: Put process  1 to run queue
	CPU 3: Dispatched process  1
READ operation failed.
read region=3 offset=20 value=105
print_pgtbl: 0 - 1024
00000000: 80000001
Time slot  24
00000004: 80000000
00000008: 80000003
00000012: 80000002
MEMORY_dump.
	CPU 2: Put process  4 to run queue
	CPU 2: Dispatched process  4
Time slot  25
	CPU 1: Put process  7 to run queue
	CPU 1: Dispatched process  7
Time slot  26
	CPU 3: Put process  1 to run queue
	CPU 1: Processed  7 has finished
	CPU 3: Dispatched process  1
	CPU 1 stopped
	CPU 2: Put process  4 to run queue
	CPU 2: Dispatched process  4
Time slot  27
	CPU 2: Processed  4 has finished
	CPU 2 stopped
Time slot  28
	CPU 3: Processed  1 has finished
	CPU 3 stopped
